[2022-08-04 00:15:14,492] {taskinstance.py:1179} INFO - Dependencies all met for <TaskInstance: secret_vars.test_conn manual__2022-08-03T21:15:07.516793+00:00 [queued]>
[2022-08-04 00:15:14,495] {taskinstance.py:1179} INFO - Dependencies all met for <TaskInstance: secret_vars.test_conn manual__2022-08-03T21:15:07.516793+00:00 [queued]>
[2022-08-04 00:15:14,495] {taskinstance.py:1376} INFO - 
--------------------------------------------------------------------------------
[2022-08-04 00:15:14,495] {taskinstance.py:1377} INFO - Starting attempt 1 of 2
[2022-08-04 00:15:14,495] {taskinstance.py:1378} INFO - 
--------------------------------------------------------------------------------
[2022-08-04 00:15:14,500] {taskinstance.py:1397} INFO - Executing <Task(PythonOperator): test_conn> on 2022-08-03 21:15:07.516793+00:00
[2022-08-04 00:15:14,503] {standard_task_runner.py:52} INFO - Started process 47206 to run task
[2022-08-04 00:15:14,504] {standard_task_runner.py:79} INFO - Running: ['airflow', 'tasks', 'run', 'secret_vars', 'test_conn', 'manual__2022-08-03T21:15:07.516793+00:00', '--job-id', '16', '--raw', '--subdir', 'DAGS_FOLDER/task_dag.py', '--cfg-path', '/tmp/tmpeimoxolj', '--error-file', '/tmp/tmp6pcekk5k']
[2022-08-04 00:15:14,504] {standard_task_runner.py:80} INFO - Job 16: Subtask test_conn
[2022-08-04 00:15:14,524] {task_command.py:371} INFO - Running <TaskInstance: secret_vars.test_conn manual__2022-08-03T21:15:07.516793+00:00 [running]> on host ndx-Victus
[2022-08-04 00:15:14,545] {taskinstance.py:1589} INFO - Exporting the following env vars:
AIRFLOW_CTX_DAG_OWNER=airflow
AIRFLOW_CTX_DAG_ID=secret_vars
AIRFLOW_CTX_TASK_ID=test_conn
AIRFLOW_CTX_EXECUTION_DATE=2022-08-03T21:15:07.516793+00:00
AIRFLOW_CTX_TRY_NUMBER=1
AIRFLOW_CTX_DAG_RUN_ID=manual__2022-08-03T21:15:07.516793+00:00
[2022-08-04 00:15:14,547] {base.py:68} INFO - Using connection ID 'mongo_test_hook' for task execution.
[2022-08-04 00:15:14,550] {taskinstance.py:1909} ERROR - Task failed with exception
Traceback (most recent call last):
  File "/home/ndx/Innowise tasks/Innowise_task_5/airflow_env/lib/python3.8/site-packages/airflow/operators/python.py", line 171, in execute
    return_value = self.execute_callable()
  File "/home/ndx/Innowise tasks/Innowise_task_5/airflow_env/lib/python3.8/site-packages/airflow/operators/python.py", line 189, in execute_callable
    return self.python_callable(*self.op_args, **self.op_kwargs)
  File "/home/ndx/Innowise tasks/Innowise_task_5/airflow/dags/task_dag.py", line 17, in test_conn
    print(hook.find("users", {}))
  File "/home/ndx/Innowise tasks/Innowise_task_5/airflow/dags/mongo_hook.py", line 136, in find
    collection = self.get_collection(mongo_collection, mongo_db=mongo_db)
  File "/home/ndx/Innowise tasks/Innowise_task_5/airflow/dags/mongo_hook.py", line 109, in get_collection
    return mongo_conn.get_database(mongo_db).get_collection(mongo_collection)
  File "/home/ndx/Innowise tasks/Innowise_task_5/airflow_env/lib/python3.8/site-packages/pymongo/mongo_client.py", line 2011, in get_database
    return database.Database(
  File "/home/ndx/Innowise tasks/Innowise_task_5/airflow_env/lib/python3.8/site-packages/pymongo/database.py", line 137, in __init__
    _check_name(name)
  File "/home/ndx/Innowise tasks/Innowise_task_5/airflow_env/lib/python3.8/site-packages/pymongo/database.py", line 50, in _check_name
    raise InvalidName("database name cannot be the empty string")
pymongo.errors.InvalidName: database name cannot be the empty string
[2022-08-04 00:15:14,552] {taskinstance.py:1415} INFO - Marking task as UP_FOR_RETRY. dag_id=secret_vars, task_id=test_conn, execution_date=20220803T211507, start_date=20220803T211514, end_date=20220803T211514
[2022-08-04 00:15:14,557] {standard_task_runner.py:92} ERROR - Failed to execute job 16 for task test_conn (database name cannot be the empty string; 47206)
[2022-08-04 00:15:14,596] {local_task_job.py:156} INFO - Task exited with return code 1
[2022-08-04 00:15:14,606] {local_task_job.py:273} INFO - 0 downstream tasks scheduled from follow-on schedule check
