[2022-08-04 00:06:35,115] {taskinstance.py:1179} INFO - Dependencies all met for <TaskInstance: secret_vars.test_conn manual__2022-08-03T21:01:26.234348+00:00 [queued]>
[2022-08-04 00:06:35,118] {taskinstance.py:1179} INFO - Dependencies all met for <TaskInstance: secret_vars.test_conn manual__2022-08-03T21:01:26.234348+00:00 [queued]>
[2022-08-04 00:06:35,118] {taskinstance.py:1376} INFO - 
--------------------------------------------------------------------------------
[2022-08-04 00:06:35,118] {taskinstance.py:1377} INFO - Starting attempt 2 of 2
[2022-08-04 00:06:35,118] {taskinstance.py:1378} INFO - 
--------------------------------------------------------------------------------
[2022-08-04 00:06:35,124] {taskinstance.py:1397} INFO - Executing <Task(PythonOperator): test_conn> on 2022-08-03 21:01:26.234348+00:00
[2022-08-04 00:06:35,128] {standard_task_runner.py:52} INFO - Started process 45938 to run task
[2022-08-04 00:06:35,130] {standard_task_runner.py:79} INFO - Running: ['airflow', 'tasks', 'run', 'secret_vars', 'test_conn', 'manual__2022-08-03T21:01:26.234348+00:00', '--job-id', '11', '--raw', '--subdir', 'DAGS_FOLDER/task_dag.py', '--cfg-path', '/tmp/tmp8td_m8eq', '--error-file', '/tmp/tmp81f8z152']
[2022-08-04 00:06:35,131] {standard_task_runner.py:80} INFO - Job 11: Subtask test_conn
[2022-08-04 00:06:35,153] {task_command.py:371} INFO - Running <TaskInstance: secret_vars.test_conn manual__2022-08-03T21:01:26.234348+00:00 [running]> on host ndx-Victus
[2022-08-04 00:06:35,174] {taskinstance.py:1589} INFO - Exporting the following env vars:
AIRFLOW_CTX_DAG_OWNER=airflow
AIRFLOW_CTX_DAG_ID=secret_vars
AIRFLOW_CTX_TASK_ID=test_conn
AIRFLOW_CTX_EXECUTION_DATE=2022-08-03T21:01:26.234348+00:00
AIRFLOW_CTX_TRY_NUMBER=2
AIRFLOW_CTX_DAG_RUN_ID=manual__2022-08-03T21:01:26.234348+00:00
[2022-08-04 00:06:35,179] {taskinstance.py:1909} ERROR - Task failed with exception
Traceback (most recent call last):
  File "/home/ndx/Innowise tasks/Innowise_task_5/airflow_env/lib/python3.8/site-packages/airflow/operators/python.py", line 171, in execute
    return_value = self.execute_callable()
  File "/home/ndx/Innowise tasks/Innowise_task_5/airflow_env/lib/python3.8/site-packages/airflow/operators/python.py", line 189, in execute_callable
    return self.python_callable(*self.op_args, **self.op_kwargs)
  File "/home/ndx/Innowise tasks/Innowise_task_5/airflow/dags/task_dag.py", line 16, in test_conn
    hook = MongoHook(conn_id="mongo_test_hook")
  File "/home/ndx/Innowise tasks/Innowise_task_5/airflow/dags/mongo_hook.py", line 53, in __init__
    self.connection = self.get_connection(conn_id)
  File "/home/ndx/Innowise tasks/Innowise_task_5/airflow_env/lib/python3.8/site-packages/airflow/hooks/base.py", line 67, in get_connection
    conn = Connection.get_connection_from_secrets(conn_id)
  File "/home/ndx/Innowise tasks/Innowise_task_5/airflow_env/lib/python3.8/site-packages/airflow/models/connection.py", line 430, in get_connection_from_secrets
    raise AirflowNotFoundException(f"The conn_id `{conn_id}` isn't defined")
airflow.exceptions.AirflowNotFoundException: The conn_id `mongo_test_hook` isn't defined
[2022-08-04 00:06:35,181] {taskinstance.py:1415} INFO - Marking task as FAILED. dag_id=secret_vars, task_id=test_conn, execution_date=20220803T210126, start_date=20220803T210635, end_date=20220803T210635
[2022-08-04 00:06:35,186] {standard_task_runner.py:92} ERROR - Failed to execute job 11 for task test_conn (The conn_id `mongo_test_hook` isn't defined; 45938)
[2022-08-04 00:06:35,222] {local_task_job.py:156} INFO - Task exited with return code 1
[2022-08-04 00:06:35,234] {local_task_job.py:273} INFO - 0 downstream tasks scheduled from follow-on schedule check
